#VRML_SIM R2023a utf8

EXTERNPROTO "https://raw.githubusercontent.com/cyberbotics/webots/R2023a/projects/objects/backgrounds/protos/TexturedBackground.proto"
EXTERNPROTO "https://raw.githubusercontent.com/cyberbotics/webots/R2023a/projects/objects/backgrounds/protos/TexturedBackgroundLight.proto"
EXTERNPROTO "https://raw.githubusercontent.com/cyberbotics/webots/R2023a/projects/objects/floors/protos/RectangleArena.proto"
EXTERNPROTO "https://raw.githubusercontent.com/cyberbotics/webots/R2023a/projects/appearances/protos/Copper.proto"
EXTERNPROTO "https://raw.githubusercontent.com/cyberbotics/webots/R2023a/projects/appearances/protos/GlossyPaint.proto"
EXTERNPROTO "https://raw.githubusercontent.com/cyberbotics/webots/R2023a/projects/objects/toys/protos/RubberDuck.proto"
EXTERNPROTO "https://raw.githubusercontent.com/cyberbotics/webots/R2023a/projects/appearances/protos/Parquetry.proto"

WorldInfo {
}
Viewpoint {
  orientation 0.18593366860578311 -0.016999023788690438 -0.9824152401449332 3.759524654522877
  position 1.4284818176380245 -1.2936657999716659 0.7761042319443999
}
TexturedBackground {
}
TexturedBackgroundLight {
}
RectangleArena {
  translation -0.00302408 -0.0454882 -1.38778e-17
  floorSize 5 5
  floorAppearance Parquetry {
  }
}
Robot {
  translation 0.4196059105548147 -0.2139696161565078 0.045936309877038416
  rotation -0.0003395831521782428 0.00045135460511823715 -0.9999998404811388 1.9272239974892194
  children [
    DEF IR_ds Solid {
      translation 0 0.04 0.009
      children [
        DEF IR_0_ds DistanceSensor {
          translation 0.03 0 0
          rotation 0 -1 0 -5.307179586466759e-06
          scale 3 3 3
          name "right_ds"
          lookupTable [
            0 0 0
            0.3 1000 0
          ]
        }
        DEF IR_1 DistanceSensor {
          translation 0.012 0 0
          rotation 0 1 0 1.5708
          name "IR_1"
          type "infra-red"
        }
        DEF IR_2 DistanceSensor {
          rotation 0 1 0 1.5708
          name "IR_2"
          type "infra-red"
        }
        DEF IR_3_ds DistanceSensor {
          rotation 0.5773509358554485 0.5773509358554485 0.5773489358556708 2.0944
          scale 3 3 3
          name "front_ds"
          lookupTable [
            0 0 0
            0.3 1000 0
          ]
        }
        DEF IR_5_ds DistanceSensor {
          translation -0.03 0 2.20392e-07
          rotation 0 1 0 -3.1415853071795863
          scale 3 3 3
          name "left_ds"
          lookupTable [
            0 0 0
            0.3 1000 0
          ]
        }
        DEF IR_4 DistanceSensor {
          translation -0.012 0 1.8366e-07
          rotation 0 1 0 1.5708
          name "IR_4"
          type "infra-red"
        }
        Shape {
          appearance PBRAppearance {
          }
          geometry Box {
            size 0.066 0.005 0.003
          }
        }
      ]
      name "distance sensor"
    }
    Group {
      children [
        DEF CUERPOROBOT Transform {
          translation 0 0 0.015
          children [
            Shape {
              appearance GlossyPaint {
                baseColor 0.698039 0.643137 0.0470588
              }
              geometry Box {
                size 0.06 0.07 0.02
              }
            }
          ]
        }
        DEF FRONT_RIGHT_WHEEL HingeJoint {
          jointParameters HingeJointParameters {
            position -914.5751149854899
            anchor 0.039 0.018 0.02
          }
          device [
            RotationalMotor {
              name "MOTOR_FRONT_RIGHT"
            }
          ]
          endPoint Solid {
            translation 0.03899999999827967 0.017998609360949713 0.019996427404491417
            rotation 0.7003649023222791 0.13187803137155849 0.701496392319067 2.8797680646924864
            children [
              DEF RUEDA Shape {
                appearance Copper {
                }
                geometry Cylinder {
                  height 0.019
                  radius 0.02
                }
              }
            ]
            boundingObject USE RUEDA
            physics Physics {
            }
            linearVelocity 0.0935835448362561 -0.034759264329078186 0.00012554573182152858
            angularVelocity 1.7411836831678826 4.6864994144619985 0.0006454700984564535
          }
        }
        DEF FRONT_LEFT_WHEEL HingeJoint {
          jointParameters HingeJointParameters {
            position -1689.5596040567334
            anchor -0.039 0.018 0.02
          }
          device [
            RotationalMotor {
              name "MOTOR_FRONT_LEFT"
            }
          ]
          endPoint Solid {
            translation -0.038999999836121346 0.01799770146678959 0.020003235450293
            rotation -0.2906334955278408 -0.9116269926380784 -0.29063447416113847 4.619992986955472
            children [
              USE RUEDA
            ]
            name "solid(1)"
            boundingObject USE RUEDA
            physics Physics {
            }
            linearVelocity 0.09359424857637898 -0.03476221275643415 -0.00013697711647107631
            angularVelocity 1.7411837596158772 4.686499836435965 0.0006454043092395575
          }
        }
        DEF BACK_RIGHT_WHEEL HingeJoint {
          jointParameters HingeJointParameters {
            position -201.34120218679396
            anchor 0.039 -0.03 0.02
          }
          device [
            RotationalMotor {
              name "MOTOR_BACK_RIGHT"
            }
          ]
          endPoint Solid {
            translation 0.0390000000692877 -0.029999374173499113 0.020002186087188383
            rotation -0.13785415081772573 0.9808121659886557 -0.13785401028249117 1.590168405312423
            children [
              USE RUEDA
            ]
            name "solid(2)"
            boundingObject USE RUEDA
            physics Physics {
            }
            linearVelocity 0.09360258551319109 -0.0347752931682397 9.527719648677973e-05
            angularVelocity 1.741183761735399 4.686499745250162 0.0006454412400402874
          }
        }
        DEF BACK_LEFT_WHEEL HingeJoint {
          jointParameters HingeJointParameters {
            position -1689.6226565163506
            anchor -0.039 -0.03 0.02
          }
          device [
            RotationalMotor {
              name "MOTOR_BACK_LEFT"
            }
          ]
          endPoint Solid {
            translation -0.038999999941102544 -0.030001267698899225 0.020002046287288563
            rotation -0.2638669407787633 -0.9277650598256711 -0.2638678292833846 4.6374790246064785
            children [
              USE RUEDA
            ]
            name "solid(3)"
            boundingObject USE RUEDA
            physics Physics {
            }
            linearVelocity 0.09358752828927795 -0.03477161314658933 -0.0001675629308917199
            angularVelocity 1.741183644602033 4.686499532677832 0.000645571149227746
          }
        }
      ]
    }
  ]
  boundingObject USE CUERPOROBOT
  physics Physics {
    mass 0.21
  }
  controller "Pololo_Controller"
  linearVelocity 0.09358456600542142 -0.034781825549376415 -2.4140544977261157e-05
  angularVelocity -0.003477058285332981 0.0007597111450065702 0.00020885063738572282
}
RubberDuck {
  translation -1.4198325250527266 -0.8296549791274346 0.11307462150064244
  rotation -4.50309568461859e-07 -4.506880237738284e-07 -0.999999999999797 1.5699560731670676
  scale 6
}
DEF Dojo Solid {
  translation 0.0007057464131239408 -0.000335447436603179 -0.003818949346865599
  rotation 0.228247359007459 0.4398080963924879 0.8686034661764459 0.0004992133067298195
  children [
    Shape {
      appearance GlossyPaint {
      }
      geometry Cylinder {
        height 0.1
        radius 0.66
      }
    }
    Shape {
      appearance GlossyPaint {
        baseColor 0 0 0
      }
      geometry Cylinder {
        height 0.1001
        radius 0.56
      }
    }
  ]
  boundingObject Cylinder {
    height 0.1
    radius 0.66
  }
  physics Physics {
  }
  locked TRUE
  linearVelocity 2.540950667388467e-06 -9.577243453635936e-07 -5.938456307772001e-08
  angularVelocity 1.930119024166306e-05 5.1366117593497686e-05 -2.0266888337285333e-09
}
