#VRML_SIM R2023a utf8

EXTERNPROTO "https://raw.githubusercontent.com/cyberbotics/webots/R2023a/projects/objects/backgrounds/protos/TexturedBackground.proto"
EXTERNPROTO "https://raw.githubusercontent.com/cyberbotics/webots/R2023a/projects/objects/backgrounds/protos/TexturedBackgroundLight.proto"
EXTERNPROTO "https://raw.githubusercontent.com/cyberbotics/webots/R2023a/projects/objects/floors/protos/RectangleArena.proto"
EXTERNPROTO "https://raw.githubusercontent.com/cyberbotics/webots/R2023a/projects/appearances/protos/Copper.proto"
EXTERNPROTO "https://raw.githubusercontent.com/cyberbotics/webots/R2023a/projects/appearances/protos/PaintedWood.proto"
EXTERNPROTO "https://raw.githubusercontent.com/cyberbotics/webots/R2023a/projects/appearances/protos/GlossyPaint.proto"

WorldInfo {
}
Viewpoint {
  orientation -0.29937404240285975 -0.36147365391524894 0.8830130125091757 4.776425218292626
  position 0.15280978817941837 1.5940590530035594 1.0877584029808534
}
TexturedBackground {
}
TexturedBackgroundLight {
}
RectangleArena {
  translation -0.00302408 -0.0454882 -1.38778e-17
  floorSize 5 5
}
Robot {
  translation 0.0039042842513790565 -0.04198196170129252 -6.506999724587188e-05
  rotation -0.0029596271298765373 -0.0010880864735094468 0.9999950283251803 0.14986310806293232
  children [
    Group {
      children [
        DEF Sensor_dist_left Solid {
          translation -0.0325 -0.006 0.02
          scale 0.05 0.05 0.05
          children [
            DEF ds_left DistanceSensor {
              rotation 0 0 1 3.14
              name "ds_left"
            }
            Shape {
              appearance PaintedWood {
                colorOverride 0.666667 0 0
              }
              geometry Box {
                size 0.1 0.1 0.1
              }
              castShadows FALSE
            }
          ]
          name "solid(4)"
        }
        DEF Sensor_dist_front_1 Solid {
          translation -0.02 0.0375 0.02
          scale 0.05 0.05 0.05
          children [
            DEF ds_front1 DistanceSensor {
              rotation 0 0 1 1.57
              name "ds_front1"
            }
            Shape {
              appearance PaintedWood {
                colorOverride 0.666667 0 0
              }
              geometry Box {
                size 0.1 0.1 0.1
              }
              castShadows FALSE
            }
          ]
          name "solid(6)"
        }
        DEF Sensor_dist_front_2 Solid {
          translation 0.02 0.0375 0.02
          scale 0.05 0.05 0.05
          children [
            DEF ds_front2 DistanceSensor {
              rotation 0 0 1 1.57
              name "ds_front2"
            }
            Shape {
              appearance PaintedWood {
                colorOverride 0.666667 0 0
              }
              geometry Box {
                size 0.1 0.1 0.1
              }
              castShadows FALSE
            }
          ]
          name "solid(7)"
        }
        DEF Sensor_dist_right Solid {
          translation 0.0325 -0.006 0.02
          scale 0.05 0.05 0.05
          children [
            DEF ds_right DistanceSensor {
              name "ds_right"
            }
            Shape {
              appearance PaintedWood {
                colorOverride 0.666667 0 0
              }
              geometry Box {
                size 0.1 0.1 0.1
              }
              castShadows FALSE
            }
          ]
          name "solid(5)"
        }
        DEF CUERPOROBOT Transform {
          translation 0 0 0.015
          children [
            Shape {
              appearance GlossyPaint {
                baseColor 0.698039 0.643137 0.0470588
              }
              geometry Box {
                size 0.06 0.07 0.02
              }
            }
          ]
        }
        DEF RUEDA1 HingeJoint {
          jointParameters HingeJointParameters {
            position -476.97720684915834
            anchor 0.039 0.018 0.02
          }
          device [
            RotationalMotor {
              name "Motor1"
            }
          ]
          endPoint Solid {
            translation 0.03899999999827967 0.017998011478231483 0.02000327766636687
            rotation 0.25944734233798217 0.9301378820670467 0.259866498220888 1.6447654934434186
            children [
              DEF RUEDA Shape {
                appearance Copper {
                }
                geometry Cylinder {
                  height 0.019
                  radius 0.02
                }
              }
            ]
            boundingObject USE RUEDA
            physics Physics {
            }
            linearVelocity -0.012628785142038608 0.08922892814033848 7.712036665179742e-06
            angularVelocity -4.14785380785294 -0.6601900413865615 -0.38189283259966417
          }
        }
        DEF RUEDA2 HingeJoint {
          jointParameters HingeJointParameters {
            position -681.3895032664587
            anchor -0.039 0.018 0.02
          }
          device [
            RotationalMotor {
              name "Motor2"
            }
          ]
          endPoint Solid {
            translation -0.038999999836121346 0.01800131060932101 0.019996253842405134
            rotation -0.7020719336087832 0.11910785285612474 -0.7020742976543352 2.9044947428527177
            children [
              USE RUEDA
            ]
            name "solid(1)"
            boundingObject USE RUEDA
            physics Physics {
            }
            linearVelocity -0.01714582119850874 0.1178324434681843 -8.156234937751145e-06
            angularVelocity -5.924613144847347 -0.9485040619371199 -0.387887783206276
          }
        }
        DEF RUEDA3 HingeJoint {
          jointParameters HingeJointParameters {
            position -477.04199368284833
            anchor 0.039 -0.03 0.02
          }
          device [
            RotationalMotor {
              name "Motor3"
            }
          ]
          endPoint Solid {
            translation 0.0390000000692877 -0.03000105113456987 0.020002016371027536
            rotation 0.2312993483956829 0.9449874771354271 0.231299112598715 1.6273487424151385
            children [
              USE RUEDA
            ]
            name "solid(2)"
            boundingObject USE RUEDA
            physics Physics {
            }
            linearVelocity -0.03022006135953058 0.08644869880019676 2.7050024421414762e-06
            angularVelocity -4.147853691171449 -0.6601900801431451 -0.38189291015608784
          }
        }
        DEF RUEDA4 HingeJoint {
          jointParameters HingeJointParameters {
            position -681.4525460609339
            anchor -0.039 -0.03 0.02
          }
          device [
            RotationalMotor {
              name "Motor4"
            }
          ]
          endPoint Solid {
            translation -0.038999999941102544 -0.029999349795799865 0.01999768233163196
            rotation -0.703792441235846 0.09669055569493121 -0.7037948110768463 2.948811473345725
            children [
              USE RUEDA
            ]
            name "solid(3)"
            boundingObject USE RUEDA
            physics Physics {
            }
            linearVelocity -0.03473633194657629 0.11504445012542466 -1.8892524177618726e-06
            angularVelocity -5.924613102502713 -0.9485041803338455 -0.3878879784087938
          }
        }
      ]
    }
  ]
  boundingObject USE CUERPOROBOT
  physics Physics {
    mass 0.21
  }
  controller "Pololo_Controller"
  linearVelocity -0.02148364957485779 0.10247570408620596 -6.703543091714011e-07
  angularVelocity -6.258864874086192e-05 0.0001724324902081569 -0.370951653646434
}
