#VRML_SIM R2023a utf8

EXTERNPROTO "https://raw.githubusercontent.com/cyberbotics/webots/R2023a/projects/objects/backgrounds/protos/TexturedBackground.proto"
EXTERNPROTO "https://raw.githubusercontent.com/cyberbotics/webots/R2023a/projects/objects/backgrounds/protos/TexturedBackgroundLight.proto"
EXTERNPROTO "https://raw.githubusercontent.com/cyberbotics/webots/R2023a/projects/objects/floors/protos/RectangleArena.proto"
EXTERNPROTO "https://raw.githubusercontent.com/cyberbotics/webots/R2023a/projects/appearances/protos/Copper.proto"
EXTERNPROTO "https://raw.githubusercontent.com/cyberbotics/webots/R2023a/projects/appearances/protos/GlossyPaint.proto"
EXTERNPROTO "https://raw.githubusercontent.com/cyberbotics/webots/R2023a/projects/objects/toys/protos/RubberDuck.proto"
EXTERNPROTO "https://raw.githubusercontent.com/cyberbotics/webots/R2023a/projects/appearances/protos/Parquetry.proto"

WorldInfo {
}
Viewpoint {
  orientation 0.25804101770744614 0.30068158096468056 -0.918153266099449 1.6473082781236663
  position -0.0017635238979404689 1.54750041795165 1.1579579616342928
}
TexturedBackground {
}
TexturedBackgroundLight {
}
RectangleArena {
  translation -0.00302408 -0.0454882 -1.38778e-17
  floorSize 5 5
  floorAppearance Parquetry {
  }
}
Robot {
  translation -0.04129536755822212 -0.04204576311542143 0.04596807845383402
  rotation 0.0001847834801095572 -0.0004764080533640983 0.9999998694452075 -1.9283750130251978
  children [
    DEF IR_ds Solid {
      translation 0 0.04 0.009
      children [
        DEF IR_0 DistanceSensor {
          translation 0.03 0 0
          rotation 0 1 0 1.5708
          name "IR_0"
          type "infra-red"
        }
        DEF IR_1 DistanceSensor {
          translation 0.017 0 0
          rotation 0 1 0 1.5708
          name "IR_1"
          type "infra-red"
        }
        DEF IR_2 DistanceSensor {
          translation 0.005 0 0
          rotation 0 1 0 1.5708
          name "IR_2"
          type "infra-red"
        }
        DEF IR_3 DistanceSensor {
          translation -0.005 0 0
          rotation 0 1 0 1.5708
          name "IR_3"
          type "infra-red"
        }
        DEF IR_5 DistanceSensor {
          translation -0.03 0 2.20392e-07
          rotation 0 1 0 1.5708
          name "IR_5"
          type "infra-red"
        }
        DEF IR_4 DistanceSensor {
          translation -0.017 0 1.8366e-07
          rotation 0 1 0 1.5708
          name "IR_4"
          type "infra-red"
        }
        Shape {
          appearance PBRAppearance {
          }
          geometry Box {
            size 0.066 0.005 0.003
          }
        }
      ]
      name "distance sensor"
    }
    DEF front_left_ds DistanceSensor {
      translation -0.02 0.037 0.02
      rotation 0 0 -1 -1.5707953071795862
      children [
        Shape {
          appearance PBRAppearance {
          }
          geometry Box {
            size 0.005 0.005 0.005
          }
        }
      ]
      name "front_left_ds"
    }
    DEF front_rigth_ds DistanceSensor {
      translation 0.02 0.037 0.02
      rotation 0 0 -1 -1.5707953071795862
      children [
        Shape {
          appearance PBRAppearance {
          }
          geometry Box {
            size 0.005 0.005 0.005
          }
        }
      ]
      name "front_right_ds"
    }
    DEF left_ds DistanceSensor {
      translation -0.03 -0.006 0.02
      rotation 0 0 1 3.14159
      children [
        Shape {
          appearance PBRAppearance {
          }
          geometry Box {
            size 0.005 0.005 0.005
          }
        }
      ]
      name "left_ds"
      resolution 1
    }
    DEF right_ds DistanceSensor {
      translation 0.03 -0.0060003 0.02
      rotation 0 0 1 -5.307179586466759e-06
      children [
        Shape {
          appearance PBRAppearance {
          }
          geometry Box {
            size 0.005 0.005 0.005
          }
        }
      ]
      name "right_ds"
      resolution 1
    }
    Group {
      children [
        DEF CUERPOROBOT Transform {
          translation 0 0 0.015
          children [
            Shape {
              appearance GlossyPaint {
                baseColor 0.698039 0.643137 0.0470588
              }
              geometry Box {
                size 0.06 0.07 0.02
              }
            }
          ]
        }
        DEF FRONT_RIGHT_WHEEL HingeJoint {
          jointParameters HingeJointParameters {
            position -889.9351152349191
            anchor 0.039 0.018 0.02
          }
          device [
            RotationalMotor {
              name "MOTOR_FRONT_RIGHT"
            }
          ]
          endPoint Solid {
            translation 0.03899999999827967 0.017997084800954268 0.019997510234918723
            rotation 0.6716548653423715 0.3103234951816944 0.6727399722033304 2.540704377107029
            children [
              DEF RUEDA Shape {
                appearance Copper {
                }
                geometry Cylinder {
                  height 0.019
                  radius 0.02
                }
              }
            ]
            boundingObject USE RUEDA
            physics Physics {
            }
          }
        }
        DEF FRONT_LEFT_WHEEL HingeJoint {
          jointParameters HingeJointParameters {
            position -1664.919603799056
            anchor -0.039 0.018 0.02
          }
          device [
            RotationalMotor {
              name "MOTOR_FRONT_LEFT"
            }
          ]
          endPoint Solid {
            translation -0.038999999836121346 0.01799950540698882 0.020003937863795396
            rotation -0.06209085791647082 -0.9961372519703494 -0.062091066991615165 4.708515395127787
            children [
              USE RUEDA
            ]
            name "solid(1)"
            boundingObject USE RUEDA
            physics Physics {
            }
          }
        }
        DEF BACK_RIGHT_WHEEL HingeJoint {
          jointParameters HingeJointParameters {
            position -176.70120249956537
            anchor 0.039 -0.03 0.02
          }
          device [
            RotationalMotor {
              name "MOTOR_BACK_RIGHT"
            }
          ]
          endPoint Solid {
            translation 0.0390000000692877 -0.02999841450886329 0.020001629985846515
            rotation -0.35234778352830504 0.8670076885540794 -0.35234742432832267 1.7130208209407234
            children [
              USE RUEDA
            ]
            name "solid(2)"
            boundingObject USE RUEDA
            physics Physics {
            }
          }
        }
        DEF BACK_LEFT_WHEEL HingeJoint {
          jointParameters HingeJointParameters {
            position -1664.982657082593
            anchor -0.039 -0.03 0.02
          }
          device [
            RotationalMotor {
              name "MOTOR_BACK_LEFT"
            }
          ]
          endPoint Solid {
            translation -0.038999999941102544 -0.030000148909928546 0.02000240253574367
            rotation -0.03070523787760159 -0.9990567403227809 -0.030705341269877593 4.711441908461292
            children [
              USE RUEDA
            ]
            name "solid(3)"
            boundingObject USE RUEDA
            physics Physics {
            }
          }
        }
      ]
    }
  ]
  boundingObject USE CUERPOROBOT
  physics Physics {
    mass 0.21
  }
  controller "Pololo_Controller"
}
RubberDuck {
  translation -1.4198325250536485 -0.8296549791245624 0.11307462149747817
  rotation -4.503058663772758e-07 -4.5069177967865425e-07 -0.999999999999797 1.5699560731670676
  scale 6
}
DEF Dojo Solid {
  translation 0.0006937208430961473 -0.00033110702918455226 -0.003818945157518307
  rotation 0.05913553573179966 -0.05567052225155622 0.9966964339085157 0.0004350711077837942
  children [
    Shape {
      appearance GlossyPaint {
      }
      geometry Cylinder {
        height 0.1
        radius 0.66
      }
    }
    Shape {
      appearance GlossyPaint {
        baseColor 0 0 0
      }
      geometry Cylinder {
        height 0.1001
        radius 0.56
      }
    }
  ]
  boundingObject Cylinder {
    height 0.1
    radius 0.66
  }
  physics Physics {
  }
  locked TRUE
}
