#VRML_SIM R2023a utf8

EXTERNPROTO "https://raw.githubusercontent.com/cyberbotics/webots/R2023a/projects/objects/backgrounds/protos/TexturedBackground.proto"
EXTERNPROTO "https://raw.githubusercontent.com/cyberbotics/webots/R2023a/projects/objects/backgrounds/protos/TexturedBackgroundLight.proto"
EXTERNPROTO "https://raw.githubusercontent.com/cyberbotics/webots/R2023a/projects/objects/floors/protos/RectangleArena.proto"
EXTERNPROTO "https://raw.githubusercontent.com/cyberbotics/webots/R2023a/projects/appearances/protos/Copper.proto"
EXTERNPROTO "https://raw.githubusercontent.com/cyberbotics/webots/R2023a/projects/appearances/protos/GlossyPaint.proto"
EXTERNPROTO "https://raw.githubusercontent.com/cyberbotics/webots/R2023a/projects/objects/toys/protos/RubberDuck.proto"
EXTERNPROTO "https://raw.githubusercontent.com/cyberbotics/webots/R2023a/projects/appearances/protos/Parquetry.proto"

WorldInfo {
}
Viewpoint {
  orientation 0.1844410750839926 -0.08266649272017669 -0.9793608838437475 4.198668309163261
  position 0.6620607462611288 -1.38011971521411 0.7009053829176116
}
TexturedBackground {
}
TexturedBackgroundLight {
}
RectangleArena {
  translation -0.00302408 -0.0454882 -1.38778e-17
  floorSize 5 5
  floorAppearance Parquetry {
  }
}
Robot {
  translation -0.041295389905006585 -0.04204549305990837 0.046054921504272
  rotation -0.00023235394104881087 0.00037039757254142986 -0.9999999044086376 1.9283749569982633
  children [
    DEF IR_ds Solid {
      translation 0 0.04 0.009
      children [
        DEF IR_0_ds DistanceSensor {
          translation 0.03 0 0
          rotation 0 -1 0 -5.307179586466759e-06
          name "IR_0_ds"
        }
        DEF IR_1 DistanceSensor {
          translation 0.012 0 0
          rotation 0 1 0 1.5708
          name "IR_1"
          type "infra-red"
        }
        DEF IR_2 DistanceSensor {
          rotation 0 1 0 1.5708
          name "IR_2"
          type "infra-red"
        }
        DEF IR_3_ds DistanceSensor {
          rotation 0.5773509358554485 0.5773509358554485 0.5773489358556708 2.0944
          name "IR_3_ds"
        }
        DEF IR_5_ds DistanceSensor {
          translation -0.03 0 2.20392e-07
          rotation 0 1 0 -3.1415853071795863
          name "IR_5_ds"
        }
        DEF IR_4 DistanceSensor {
          translation -0.012 0 1.8366e-07
          rotation 0 1 0 1.5708
          name "IR_4"
          type "infra-red"
        }
        Shape {
          appearance PBRAppearance {
          }
          geometry Box {
            size 0.066 0.005 0.003
          }
        }
      ]
      name "distance sensor"
    }
    DEF front_left_ds DistanceSensor {
      translation -0.02 0.037 0.02
      rotation 0 0 -1 -1.5707953071795862
      children [
        Shape {
          appearance PBRAppearance {
          }
          geometry Box {
            size 0.005 0.005 0.005
          }
        }
      ]
      name "front_left_ds"
    }
    DEF front_rigth_ds DistanceSensor {
      translation 0.02 0.037 0.02
      rotation 0 0 -1 -1.5707953071795862
      children [
        Shape {
          appearance PBRAppearance {
          }
          geometry Box {
            size 0.005 0.005 0.005
          }
        }
      ]
      name "front_right_ds"
    }
    DEF left_ds DistanceSensor {
      translation -0.03 -0.006 0.02
      rotation 0 0 1 3.14159
      children [
        Shape {
          appearance PBRAppearance {
          }
          geometry Box {
            size 0.005 0.005 0.005
          }
        }
      ]
      name "left_ds"
      resolution 1
    }
    DEF right_ds DistanceSensor {
      translation 0.03 -0.0060003 0.02
      rotation 0 0 1 -5.307179586466759e-06
      children [
        Shape {
          appearance PBRAppearance {
          }
          geometry Box {
            size 0.005 0.005 0.005
          }
        }
      ]
      name "right_ds"
      resolution 1
    }
    Group {
      children [
        DEF CUERPOROBOT Transform {
          translation 0 0 0.015
          children [
            Shape {
              appearance GlossyPaint {
                baseColor 0.698039 0.643137 0.0470588
              }
              geometry Box {
                size 0.06 0.07 0.02
              }
            }
          ]
        }
        DEF FRONT_RIGHT_WHEEL HingeJoint {
          jointParameters HingeJointParameters {
            position -889.9351152633933
            anchor 0.039 0.018 0.02
          }
          device [
            RotationalMotor {
              name "MOTOR_FRONT_RIGHT"
            }
          ]
          endPoint Solid {
            translation 0.03899999999827967 0.017997084800883377 0.019997510235001733
            rotation 0.6716548629212711 0.3103235056789544 0.6727399697783184 2.5407043579821718
            children [
              DEF RUEDA Shape {
                appearance Copper {
                }
                geometry Cylinder {
                  height 0.019
                  radius 0.02
                }
              }
            ]
            boundingObject USE RUEDA
            physics Physics {
            }
          }
        }
        DEF FRONT_LEFT_WHEEL HingeJoint {
          jointParameters HingeJointParameters {
            position -1664.9196037989984
            anchor -0.039 0.018 0.02
          }
          device [
            RotationalMotor {
              name "MOTOR_FRONT_LEFT"
            }
          ]
          endPoint Solid {
            translation -0.038999999836121346 0.01799950540698859 0.020003937863795368
            rotation -0.06209085794501194 -0.9961372519667913 -0.062091067020156376 4.7085153951242145
            children [
              USE RUEDA
            ]
            name "solid(1)"
            boundingObject USE RUEDA
            physics Physics {
            }
          }
        }
        DEF BACK_RIGHT_WHEEL HingeJoint {
          jointParameters HingeJointParameters {
            position -176.70120249963557
            anchor 0.039 -0.03 0.02
          }
          device [
            RotationalMotor {
              name "MOTOR_BACK_RIGHT"
            }
          ]
          endPoint Solid {
            translation 0.0390000000692877 -0.029998414508863175 0.0200016299858464
            rotation -0.35234778355495944 0.867007688532415 -0.3523474243549772 1.713020820965458
            children [
              USE RUEDA
            ]
            name "solid(2)"
            boundingObject USE RUEDA
            physics Physics {
            }
          }
        }
        DEF BACK_LEFT_WHEEL HingeJoint {
          jointParameters HingeJointParameters {
            position -1664.982657082934
            anchor -0.039 -0.03 0.02
          }
          device [
            RotationalMotor {
              name "MOTOR_BACK_LEFT"
            }
          ]
          endPoint Solid {
            translation -0.038999999941102544 -0.030000148909927724 0.020002402535743723
            rotation -0.030705237707393362 -0.9990567403332431 -0.03070534109966881 4.711441908471764
            children [
              USE RUEDA
            ]
            name "solid(3)"
            boundingObject USE RUEDA
            physics Physics {
            }
          }
        }
      ]
    }
  ]
  boundingObject USE CUERPOROBOT
  physics Physics {
    mass 0.21
  }
  controller "Pololo_Controller"
}
RubberDuck {
  translation -1.4198325250527266 -0.8296549791274346 0.11307462150064268
  rotation -4.5030956844061546e-07 -4.50688023777982e-07 -0.999999999999797 1.5699560731670676
  scale 6
}
DEF Dojo Solid {
  translation 0.0006937177476227008 -0.00033095983446686483 -0.003818947117784224
  rotation 0.05260523908397973 -0.05605304119740887 0.997040994840954 0.0004349207334706723
  children [
    Shape {
      appearance GlossyPaint {
      }
      geometry Cylinder {
        height 0.1
        radius 0.66
      }
    }
    Shape {
      appearance GlossyPaint {
        baseColor 0 0 0
      }
      geometry Cylinder {
        height 0.1001
        radius 0.56
      }
    }
  ]
  boundingObject Cylinder {
    height 0.1
    radius 0.66
  }
  physics Physics {
  }
  locked TRUE
}
