#VRML_SIM R2023a utf8

EXTERNPROTO "https://raw.githubusercontent.com/cyberbotics/webots/R2023a/projects/objects/backgrounds/protos/TexturedBackground.proto"
EXTERNPROTO "https://raw.githubusercontent.com/cyberbotics/webots/R2023a/projects/objects/backgrounds/protos/TexturedBackgroundLight.proto"
EXTERNPROTO "https://raw.githubusercontent.com/cyberbotics/webots/R2023a/projects/objects/floors/protos/RectangleArena.proto"
EXTERNPROTO "https://raw.githubusercontent.com/cyberbotics/webots/R2023a/projects/appearances/protos/Copper.proto"
EXTERNPROTO "https://raw.githubusercontent.com/cyberbotics/webots/R2023a/projects/appearances/protos/PaintedWood.proto"
EXTERNPROTO "https://raw.githubusercontent.com/cyberbotics/webots/R2023a/projects/appearances/protos/GlossyPaint.proto"

WorldInfo {
}
Viewpoint {
  orientation -0.12094843971827596 -0.0245181647110047 0.9923559515259225 3.297716604427986
  position 1.540665620559129 2.124724563587389 0.6641835023483067
}
TexturedBackground {
}
TexturedBackgroundLight {
}
RectangleArena {
  translation -0.00302408 -0.0454882 -1.38778e-17
  floorSize 5 5
}
Robot {
  translation -0.5416957854898944 2.4162958414877425 -5.5346820776871336e-05
  rotation 0.09313295523865905 0.0016347559235159637 -0.9956523390328496 0.00985697188804737
  children [
    Group {
      children [
        DEF DS_LEFT Solid {
          translation -0.0325 -0.006 0.02
          scale 0.05 0.05 0.05
          children [
            DEF ds_left DistanceSensor {
              rotation 0 0 1 3.14
              name "ds_left"
            }
            Shape {
              appearance PaintedWood {
                colorOverride 0.666667 0 0
              }
              geometry Box {
                size 0.1 0.1 0.1
              }
              castShadows FALSE
            }
          ]
          name "solid(4)"
        }
        DEF DS_FRONT_LEFT Solid {
          translation -0.02 0.0375 0.02
          scale 0.05 0.05 0.05
          children [
            DEF ds_front_left DistanceSensor {
              rotation 0 0 1 1.57
              name "ds_front_left"
            }
            Shape {
              appearance PaintedWood {
                colorOverride 0.666667 0 0
              }
              geometry Box {
                size 0.1 0.1 0.1
              }
              castShadows FALSE
            }
          ]
          name "solid(6)"
        }
        DEF DS_FRONT_RIGHT Solid {
          translation 0.02 0.0375 0.02
          scale 0.05 0.05 0.05
          children [
            DEF ds_front_right DistanceSensor {
              rotation 0 0 1 1.57
              name "ds_front_right"
            }
            Shape {
              appearance PaintedWood {
                colorOverride 0.666667 0 0
              }
              geometry Box {
                size 0.1 0.1 0.1
              }
              castShadows FALSE
            }
          ]
          name "solid(7)"
        }
        DEF DS_RIGHT Solid {
          translation 0.0325 -0.006 0.02
          scale 0.05 0.05 0.05
          children [
            DEF ds_right DistanceSensor {
              name "ds_right"
            }
            Shape {
              appearance PaintedWood {
                colorOverride 0.666667 0 0
              }
              geometry Box {
                size 0.1 0.1 0.1
              }
              castShadows FALSE
            }
          ]
          name "solid(5)"
        }
        DEF CUERPOROBOT Transform {
          translation 0 0 0.015
          children [
            Shape {
              appearance GlossyPaint {
                baseColor 0.698039 0.643137 0.0470588
              }
              geometry Box {
                size 0.06 0.07 0.02
              }
            }
          ]
        }
        DEF FRONT_RIGHT_WHEEL HingeJoint {
          jointParameters HingeJointParameters {
            position -818.0951072634534
            anchor 0.039 0.018 0.02
          }
          device [
            RotationalMotor {
              name "MOTOR_FRONT_RIGHT"
            }
          ]
          endPoint Solid {
            translation 0.03899999999827967 0.018003673379907836 0.020001097085087415
            rotation -0.5123721801965564 0.6885496029797754 -0.5131999544008371 1.9371008129943357
            children [
              DEF RUEDA Shape {
                appearance Copper {
                }
                geometry Cylinder {
                  height 0.019
                  radius 0.02
                }
              }
            ]
            boundingObject USE RUEDA
            physics Physics {
            }
            linearVelocity 0.001969580716902038 -6.231831364354134e-06 2.540811702693919e-05
            angularVelocity -9.999704341490496 0.09858441587877621 0.00017660296940961664
          }
        }
        DEF FRONT_LEFT_WHEEL HingeJoint {
          jointParameters HingeJointParameters {
            position -1022.5074033854564
            anchor -0.039 0.018 0.02
          }
          device [
            RotationalMotor {
              name "MOTOR_FRONT_LEFT"
            }
          ]
          endPoint Solid {
            translation -0.038999999836121346 0.017996044354206504 0.019999677107023512
            rotation -0.5923183651767644 -0.5461827036913718 -0.5923203596557427 4.14140530431177
            children [
              USE RUEDA
            ]
            name "solid(1)"
            boundingObject USE RUEDA
            physics Physics {
            }
            linearVelocity 0.0019696990134095535 5.0968833782582535e-06 -2.3078625559811415e-05
            angularVelocity -9.999704329264778 0.09858437287073504 0.0001766619093623437
          }
        }
        DEF BACK_RIGHT_WHEEL HingeJoint {
          jointParameters HingeJointParameters {
            position -477.0419976246785
            anchor 0.039 -0.03 0.02
          }
          device [
            RotationalMotor {
              name "MOTOR_BACK_RIGHT"
            }
          ]
          endPoint Solid {
            translation 0.0390000000692877 -0.030001051126621686 0.02000201637517085
            rotation 0.23129758554433313 0.9449883400975811 0.23129734974914887 1.6273478306757825
            children [
              USE RUEDA
            ]
            name "solid(2)"
            boundingObject USE RUEDA
            physics Physics {
            }
            linearVelocity 0.0019726049783203776 6.241845085736704e-06 -4.376700142944195e-06
            angularVelocity -0.00018643624991190655 0.000420225417833501 6.314817183411425e-05
          }
        }
        DEF BACK_LEFT_WHEEL HingeJoint {
          jointParameters HingeJointParameters {
            position -1022.57044772589
            anchor -0.039 -0.03 0.02
          }
          device [
            RotationalMotor {
              name "MOTOR_BACK_LEFT"
            }
          ]
          endPoint Solid {
            translation -0.038999999941102544 -0.030002406738023873 0.01999995568013169
            rotation -0.5807746544332671 -0.5704378406051751 -0.5807766100435038 4.178387628919207
            children [
              USE RUEDA
            ]
            name "solid(3)"
            boundingObject USE RUEDA
            physics Physics {
            }
            linearVelocity 0.0019725994407351565 1.5926973385461926e-06 2.2227603386397547e-06
            angularVelocity -9.999704386978225 0.09858449833331442 0.00017664010228350742
          }
        }
      ]
    }
  ]
  boundingObject USE CUERPOROBOT
  physics Physics {
    mass 0.21
  }
  controller "Pololo_Controller"
  linearVelocity 0.0019686621712971526 2.702015394294763e-06 6.137819991162512e-06
  angularVelocity -0.00018633452693589734 0.00042022381104974473 6.315069888098502e-05
}
